Workbook

Sheet Ave
A1: Lower Bound | B1: Higher Bound | C1: F | D1: Count F | E1: Mid point | F1: Mid point frequency | G1: F(M-Xbar)^2
A2: 0 | B2: 3000 | C2: 73 | D2: 73 | E2: =SUM(A2:B2)/2 -> 1500 | F2: =D2*E2 -> 109500 | G2: =D2*(E2-$K$3)^2 -> 164250000
A3: 3000 | B3: 6000 | C3: 195 | D3: =C3-C2 -> 122 | E3: =SUM(A3:B3)/2 -> 4500 | F3: =D3*E3 -> 549000 | G3: =D3*(E3-$K$3)^2 -> 2470500000
A4: 6000 | B4: 9000 | C4: 322 | D4: =C4-C3 -> 127 | E4: =SUM(A4:B4)/2 -> 7500 | F4: =D4*E4 -> 952500 | G4: =D4*(E4-$K$3)^2 -> 7143750000
A5: 9000 | B5: 12000 | C5: 456 | D5: =C5-C4 -> 134 | E5: =SUM(A5:B5)/2 -> 10500 | F5: =D5*E5 -> 1407000 | G5: =D5*(E5-$K$3)^2 -> 14773500000
A6: 12000 | B6: 15000 | C6: 595 | D6: =C6-C5 -> 139 | E6: =SUM(A6:B6)/2 -> 13500 | F6: =D6*E6 -> 1876500 | G6: =D6*(E6-$K$3)^2 -> 25332750000
A7: 15000 | B7: 18000 | C7: 765 | D7: =C7-C6 -> 170 | E7: =SUM(A7:B7)/2 -> 16500 | F7: =D7*E7 -> 2805000 | G7: =D7*(E7-$K$3)^2 -> 46282500000
A8: 18000 | B8: 21000 | C8: 881 | D8: =C8-C7 -> 116 | E8: =SUM(A8:B8)/2 -> 19500 | F8: =D8*E8 -> 2262000 | G8: =D8*(E8-$K$3)^2 -> 44109000000
A9: 21000 | B9: 24000 | C9: 995 | D9: =C9-C8 -> 114 | E9: =SUM(A9:B9)/2 -> 22500 | F9: =D9*E9 -> 2565000 | G9: =D9*(E9-$K$3)^2 -> 57712500000
A10: 24000 | B10: 27000 | C10: 1040 | D10: =C10-C9 -> 45 | E10: =SUM(A10:B10)/2 -> 25500 | F10: =D10*E10 -> 1147500 | G10: =D10*(E10-$K$3)^2 -> 29261250000
A11: 27000 | B11: 30000 | C11: 1081 | D11: =C11-C10 -> 41 | E11: =SUM(A11:B11)/2 -> 28500 | F11: =D11*E11 -> 1168500 | G11: =D11*(E11-$K$3)^2 -> 33302250000
A12: 30000 | B12: 33000 | C12: 1108 | D12: =C12-C11 -> 27 | E12: =SUM(A12:B12)/2 -> 31500 | F12: =D12*E12 -> 850500 | G12: =D12*(E12-$K$3)^2 -> 26790750000
A13: 33000 | B13: 36000 | C13: 1134 | D13: =C13-C12 -> 26 | E13: =SUM(A13:B13)/2 -> 34500 | F13: =D13*E13 -> 897000 | G13: =D13*(E13-$K$3)^2 -> 30946500000
A14: 36000 | B14: 39000 | C14: 1148 | D14: =C14-C13 -> 14 | E14: =SUM(A14:B14)/2 -> 37500 | F14: =D14*E14 -> 525000 | G14: =D14*(E14-$K$3)^2 -> 19687500000
... A19: 51000 | B19: 54000 | C19: 1179 | D19: =C19-C18 -> 1 | E19: =SUM(A19:B19)/2 -> 52500 | F19: =D19*E19 -> 52500 | G19: =D19*(E19-$K$3)^2 -> 2756250000

Sheet Sample
A1: No. | B1: Price | C1: Mileage | D1: Fuel | E1: Gear | F1: Door | G1: Reg
A2: 1 | B2: 19449 | C2: 31738 | D2: Hybrid | E2: Automatic | F2: 5 | G2: 21
A3: 2 | B3: 12995 | C3: 93000 | D3: Diesel | E3: Automatic | F3: 5 | G3: 19
A4: 3 | B4: 27200 | C4: 2780 | D4: Petrol | E4: Manual | F4: 5 | G4: 25 | I4: Mean | J4: =AVERAGE(B2:B100) -> 14909.414
A5: 4 | B5: 5995 | C5: 107908 | D5: Petrol | E5: Manual | F5: 5 | G5: 15 | I5: SD | J5: =_xlfn.STDEV.S(B2:B100) -> 9812.2752
A6: 5 | B6: 30084 | C6: 201 | D6: Plug-in Hybrid | E6: Automatic | F6: 5 | G6: 25
A7: 6 | B7: 47000 | C7: 3000 | D7: Petrol | E7: Automatic | F7: 5 | G7: 25
A8: 7 | B8: 13205 | C8: 32519 | D8: Petrol | E8: Automatic | F8: 5 | G8: 21
A9: 8 | B9: 9300 | C9: 94000 | D9: Diesel | E9: Manual | F9: 5 | G9: 18
A10: 9 | B10: 9995 | C10: 61350 | D10: Petrol | E10: Automatic | F10: 5 | G10: 15
A11: 10 | B11: 7295 | C11: 61000 | D11: Diesel | E11: Automatic | F11: 5 | G11: 13
A12: 11 | B12: 8190 | C12: 81251 | D12: Diesel | E12: Manual | F12: 5 | G12: 16
A13: 12 | B13: 14811 | C13: 84649 | D13: Plug-in Hybrid | E13: Automatic | F13: 5 | G13: 21
A14: 13 | B14: 37210 | C14: 3406 | D14: Petrol | E14: Automatic | F14: 5 | G14: 25
A15: 14 | B15: 2295 | C15: 148650 | D15: Diesel | E15: Manual | F15: 5 | G15: 9
A16: 15 | B16: 4985 | C16: 85652 | D16: Petrol | E16: Automatic | F16: 5 | G16: 9
A17: 16 | B17: 3495 | C17: 111242 | D17: Petrol | E17: Manual | F17: 5 | G17: 9
... A100: 99 | B100: 11995 | C100: 91513 | D100: Diesel | E100: Automatic | F100: 5 | G100: 18

Sheet Average Year
A1: Row Labels | B1: Average of Price
A2: 2008-2011 | B2: 4609
A3: 2012-2015 | B3: 4936.3636
A4: 2016-2019 | B4: 12156.103
A5: 2020-2024 | B5: 20970.854
A6: >2024 | B6: 34129.75

Sheet Color
A1: Color | B1: Average of Price
A2: Black | B2: 19045.094
A3: Blue | B3: 14819.389
A4: Grey | B4: 13647.7
A5: Red | B5: 10777.667
A6: Silver | B6: 12576.857
A7: White | B7: 16466.476
A8: Yellow | B8: 11747.5

Sheet mileage
A3: Row Labels | B3: Average of Price
A4: 0-9999 | B4: 33703.667 | C4: =GETPIVOTDATA("Price",$A$3,"Mileage",0)-GETPIVOTDATA("Price",$A$3,"Mileage",10000) -> 8261.6667
A5: 10000-19999 | B5: 25442 | C5: =GETPIVOTDATA("Price",$A$3,"Mileage",0)-GETPIVOTDATA("Price",$A$3,"Mileage",10000) -> 8261.6667
A6: 20000-29999 | B6: 20677.286 | C6: =GETPIVOTDATA("Price",$A$3,"Mileage",0)-GETPIVOTDATA("Price",$A$3,"Mileage",10000) -> 8261.6667
A7: 30000-39999 | B7: 16151.444 | C7: =GETPIVOTDATA("Price",$A$3,"Mileage",0)-GETPIVOTDATA("Price",$A$3,"Mileage",10000) -> 8261.6667
A8: 40000-49999 | B8: 16716 | C8: =GETPIVOTDATA("Price",$A$3,"Mileage",0)-GETPIVOTDATA("Price",$A$3,"Mileage",10000) -> 8261.6667
A9: 50000-59999 | B9: 13884.143 | C9: =GETPIVOTDATA("Price",$A$3,"Mileage",0)-GETPIVOTDATA("Price",$A$3,"Mileage",10000) -> 8261.6667
A10: 60000-69999 | B10: 11409 | C10: =GETPIVOTDATA("Price",$A$3,"Mileage",0)-GETPIVOTDATA("Price",$A$3,"Mileage",10000) -> 8261.6667
A11: 70000-79999 | B11: 9896.3333 | C11: =GETPIVOTDATA("Price",$A$3,"Mileage",0)-GETPIVOTDATA("Price",$A$3,"Mileage",10000) -> 8261.6667
A12: 80000-89999 | B12: 9226.3333 | C12: =GETPIVOTDATA("Price",$A$3,"Mileage",0)-GETPIVOTDATA("Price",$A$3,"Mileage",10000) -> 8261.6667
A13: 90000-99999 | B13: 9930 | C13: =GETPIVOTDATA("Price",$A$3,"Mileage",0)-GETPIVOTDATA("Price",$A$3,"Mileage",10000) -> 8261.6667
A14: 100000-109999 | B14: 9988 | C14: =GETPIVOTDATA("Price",$A$3,"Mileage",0)-GETPIVOTDATA("Price",$A$3,"Mileage",10000) -> 8261.6667
A15: 110000-119999 | B15: 4046.25 | C15: =GETPIVOTDATA("Price",$A$3,"Mileage",0)-GETPIVOTDATA("Price",$A$3,"Mileage",10000) -> 8261.6667
... A20: 170000-179999 | B20: 4690 | C20: =GETPIVOTDATA("Price",$A$3,"Mileage",0)-GETPIVOTDATA("Price",$A$3,"Mileage",10000) -> 8261.6667
A21: Grand Total | B21: 15903.69

Sheet Engine
A1: Row Labels | B1: Average of Price
A2: 1.0L | B2: 15454.143
A3: 1.4L | B3: 8100.875
A4: 1.5L | B4: 20387
A5: 1.6L | B5: 7301.8571
A6: 2.0L | B6: 19405.846

Sheet Sample 1
A1: No. | B1: Price | C1: Mileage | D1: Fuel | E1: Gear | F1: Age of cars | G1: Fuel Consumption(mpg) | H1: Drive Type | I1: Engine Size | J1: Color | K1: Pan-roof | L1: Owner | M1: Registration Year
A2: 295 | B2: 9999 | C2: 100439 | D2: Petrol | E2: Automatic | F2: =YEAR(TODAY()) -M2 -> 18 | G2: 67.3mpg | H2: Front Wheel drive | I2: 2 | J2: Grey | K2: No | L2: 8 | M2: 2008
A3: 10 | B3: 4295 | C3: 160000 | D3: Diesel | E3: Automatic | F3: =YEAR(TODAY()) -M3 -> 10 | G3: 61.4mpg | H3: Front Wheel drive | I3: 2 | J3: Black | K3: No | L3: 5 | M3: 2016
A4: 14 | B4: 19399 | C4: 31738 | D4: Petrol Hybrid | E4: Automatic | F4: =YEAR(TODAY()) -M4 -> 5 | G4: 49.6mpg | H4: Front Wheel drive | I4: 1.5 | J4: Black | K4: No | L4: 1 | M4: 2021
A5: 17 | B5: 4985 | C5: 85652 | D5: Petrol | E5: Manual | F5: =YEAR(TODAY()) -M5 -> 17 | G5: 47.1mpg | H5: Front Wheel drive | I5: 1.4 | J5: White | K5: No | L5: 8 | M5: 2009
A6: 315 | B6: 3875 | C6: 122000 | D6: Diesel | E6: Manual | F6: =YEAR(TODAY()) -M6 -> 17 | G6: 58.9mpg | H6: Front Wheel drive | I6: 1.6 | J6: Blue | K6: No | L6: 8 | M6: 2009
A7: 24 | B7: 28000 | C7: 4791 | D7: Plug-in Hybrid | E7: Automatic | F7: 1 | G7: 282.5mpg | H7: Front Wheel drive | I7: 1.5 | J7: White | K7: No | L7: 1 | M7: 2025
A8: 28 | B8: 32464 | C8: 11383 | D8: Petrol | E8: Automatic | F8: =YEAR(TODAY()) -M8 -> 3 | G8: 37mpg | H8: Four Wheel Drive | I8: 2 | J8: Blue | K8: No | L8: 1 | M8: 2023
A9: 46 | B9: 19250 | C9: 88283 | D9: Petrol | E9: Manual | F9: =YEAR(TODAY()) -M9 -> 5 | G9: 38.2mpg | H9: Front Wheel drive | I9: 2 | J9: White | K9: Yes | L9: 1 | M9: 2021
A10: 391 | B10: 6700 | C10: 141424 | D10: Petrol | E10: Manual | F10: =YEAR(TODAY()) -M10 -> 17 | G10: 45.6mpg | H10: Front Wheel drive | I10: 1.4 | J10: Grey | K10: No | L10: 4 | M10: 2009
A11: 64 | B11: 20475 | C11: 44000 | D11: Petrol | E11: Automatic | F11: =YEAR(TODAY()) -M11 -> 9 | G11: 39.2mpg | H11: Four Wheel Drive | I11: 2 | J11: White | K11: No | L11: 2 | M11: 2017
A12: 72 | B12: 12495 | C12: 58000 | D12: Diesel | E12: Automatic | F12: =YEAR(TODAY()) -M12 -> 7 | G12: 52.3mpg | H12: Front Wheel drive | I12: 2 | J12: Blue | K12: No | L12: 4 | M12: 2019
A13: 78 | B13: 33434 | C13: 11815 | D13: Petrol | E13: Automatic | F13: =YEAR(TODAY()) -M13 -> 3 | G13: 37mpg | H13: Four Wheel Drive | I13: 2 | J13: Black | K13: No | L13: 1 | M13: 2023
A14: 99 | B14: 6950 | C14: 38000 | D14: Petrol | E14: Manual | F14: =YEAR(TODAY()) -M14 -> 9 | G14: 54.3mpg | H14: Front Wheel drive | I14: 1.4 | J14: Silver | K14: No | L14: 7 | M14: 2017
A15: 102 | B15: 30295 | C15: 1200 | D15: Plug-in Hybrid | E15: Automatic | F15: =YEAR(TODAY()) -M15 -> 2 | G15: 256.8mpg | H15: Front Wheel drive | I15: 1.5 | J15: Blue | K15: No | L15: 1 | M15: 2024
A16: 107 | B16: 12609 | C16: 49652 | D16: Diesel | E16: Manual | F16: =YEAR(TODAY()) -M16 -> 7 | G16: 55.4mpg | H16: Front Wheel drive | I16: 1.6 | J16: Black | K16: No | L16: 2 | M16: 2019
A17: 116 | B17: 24750 | C17: 59000 | D17: Petrol | E17: Automatic | F17: =YEAR(TODAY()) -M17 -> 5 | G17: 38.7mpg | H17: Front Wheel drive | I17: 2 | J17: Grey | K17: Yes | L17: 3 | M17: 2021
A18: 120 | B18: 7495 | C18: 106287 | D18: Diesel | E18: Automatic | F18: =YEAR(TODAY()) -M18 -> 8 | G18: 54.3mpg | H18: Front Wheel drive | I18: 1.6 | J18: Yellow | K18: No | L18: 3 | M18: 2018
A19: 136 | B19: 31176 | C19: 19958 | D19: Petrol | E19: Automatic | F19: =YEAR(TODAY()) -M19 -> 3 | G19: 37mpg | H19: Four Wheel Drive | I19: 2 | J19: Black | K19: No | L19: 1 | M19: 2023
... A39: 256 | B39: 20499 | C39: 25477 | D39: Plug-in Hybrid | E39: Automatic | F39: =YEAR(TODAY()) -M39 -> 3 | G39: 235.4mpg | H39: Front Wheel drive | I39: 1.4 | J39: White | K39: No | L39: 1 | M39: 2023
A40: 259 | B40: 27000 | C40: 2780 | D40: Petrol | E40: Manual | F40: 1 | G40: 50.4mpg | H40: Front Wheel drive | I40: 1.5 | J40: Grey | K40: No | L40: 1 | M40: 2025
A41: 260 | B41: 27899 | C41: 20668 | D41: Petrol | E41: Automatic | F41: =YEAR(TODAY()) -M41 -> 3 | G41: 40mpg | H41: Front Wheel drive | I41: 2 | J41: White | K41: No | L41: 1 | M41: 2023
A42: 265 | B42: 13990 | C42: 109000 | D42: Petrol | E42: Automatic | F42: =YEAR(TODAY()) -M42 -> 9 | G42: 44.8mpg | H42: Front Wheel drive | I42: 2 | J42: Silver | K42: Yes | L42: 6 | M42: 2017
A43: 271 | B43: 19999 | C43: 30624 | D43: Petrol | E43: Manual | F43: =YEAR(TODAY()) -M43 -> 4 | G43: 49.6mpg | H43: Front Wheel drive | I43: 1.5 | J43: Black | K43: No | L43: 1 | M43: 2022
A44: 272 | B44: 13995 | C44: 82500 | D44: Petrol | E44: Manual | F44: =YEAR(TODAY()) -M44 -> 9 | G44: 44.1mpg | H44: Front Wheel drive | I44: 2 | J44: Black | K44: Yes | L44: 2 | M44: 2017
A45: 277 | B45: 17000 | C45: 13213 | D45: Petrol | E45: Manual | F45: =YEAR(TODAY()) -M45 -> 3 | G45: 54.3mpg | H45: Front Wheel drive | I45: 1.5 | J45: Black | K45: No | L45: 1 | M45: 2023
A46: 338 | B46: 2395 | C46: 138633 | D46: Petrol | E46: Manual | F46: =YEAR(TODAY()) -M46 -> 16 | G46: 45.6mpg | H46: Front Wheel drive | I46: 1.4 | J46: Grey | K46: No | L46: 5 | M46: 2010
A47: 294 | B47: 27000 | C47: 2780 | D47: Petrol | E47: Manual | F47: 1 | G47: 50.4mpg | H47: Front Wheel drive | I47: 1.5 | J47: Grey | K47: No | L47: 1 | M47: 2025
A48: 178 | B48: 2990 | C48: 119000 | D48: Diesel | E48: Automatic | F48: =YEAR(TODAY()) -M48 -> 16 | G48: 61.4mpg | H48: Front Wheel drive | I48: 1.4 | J48: Black | K48: No | L48: 8 | M48: 2010
A49: 298 | B49: 22000 | C49: 47992 | D49: Petrol | E49: Automatic | F49: =YEAR(TODAY()) -M49 -> 5 | G49: 38.7mpg | H49: Front Wheel drive | I49: 2 | J49: Black | K49: No | L49: 2 | M49: 2021
A50: 302 | B50: 15197 | C50: 54111 | D50: Diesel | E50: Manual | F50: =YEAR(TODAY()) -M50 -> 5 | G50: 61.4mpg | H50: Front Wheel drive | I50: 2 | J50: Blue | K50: No | L50: 1 | M50: 2021
A51: 304 | B51: 31999 | C51: 14936 | D51: Petrol | E51: Automatic | F51: =YEAR(TODAY()) -M51 -> 3 | G51: 37mpg | H51: Four Wheel Drive | I51: 1.5 | J51: Black | K51: No | L51: 1 | M51: 2023
A52: 308 | B52: 19400 | C52: 42511 | D52: Petrol Hybrid | E52: Automatic | F52: =YEAR(TODAY()) -M52 -> 3 | G52: 54.3mpg | H52: Front Wheel drive | I52: 1.5 | J52: Black | K52: No | L52: 1 | M52: 2023
A53: 58 | B53: 3500 | C53: 112000 | D53: Diesel | E53: Manual | F53: =YEAR(TODAY()) -M53 -> 14 | G53: 62.8mpg | H53: Front Wheel drive | I53: 1.6 | J53: White | K53: No | L53: 8 | M53: 2012
A54: 317 | B54: 19749 | C54: 29842 | D54: Petrol | E54: Manual | F54: =YEAR(TODAY()) -M54 -> 4 | G54: 51.4mpg | H54: Front Wheel drive | I54: 1.5 | J54: White | K54: No | L54: 1 | M54: 2022
A55: 320 | B55: 7995 | C55: 76000 | D55: Diesel | E55: Automatic | F55: =YEAR(TODAY()) -M55 -> 10 | G55: 72.43mpg | H55: Front Wheel drive | I55: 1.6 | J55: Black | K55: No | L55: 3 | M55: 2016
A56: 321 | B56: 12684 | C56: 45570 | D56: Petrol | E56: Manual | F56: =YEAR(TODAY()) -M56 -> 7 | G56: 50.4mpg | H56: Front Wheel drive | I56: 1.5 | J56: Red | K56: No | L56: 2 | M56: 2019
A57: 176 | B57: 6700 | C57: 111000 | D57: Petrol | E57: Automatic | F57: =YEAR(TODAY()) -M57 -> 14 | G57: 70.6mpg | H57: Front Wheel drive | I57: 1.4 | J57: Silver | K57: No | L57: 4 | M57: 2012
A58: 343 | B58: 14649 | C58: 34528 | D58: Petrol | E58: Automatic | F58: =YEAR(TODAY()) -M58 -> 7 | G58: 45.6mpg | H58: Front Wheel drive | I58: 1 | J58: Red | K58: No | L58: 3 | M58: 2019
A59: 344 | B59: 14950 | C59: 104716 | D59: Petrol | E59: Automatic | F59: =YEAR(TODAY()) -M59 -> 8 | G59: 40.4mpg | H59: Four Wheel Drive | I59: 2 | J59: Blue | K59: Yes | L59: 2 | M59: 2018
...

Sheet Corelation
C2: Price | D2: Age of Car | E2: Engine Size | F2: Mileage | G2: Owner count
B3: Price | C3: =CORREL('Sample 1'!B:B,'Sample 1'!B:B) -> 1
B4: Age of Car | C4: =CORREL('Sample 1'!F:F,'Sample 1'!B:B) -> -0.81349487 | D4: =CORREL('Sample 1'!F:F,'Sample 1'!F:F) -> 1
B5: Engine Size | C5: =CORREL('Sample 1'!I:I,'Sample 1'!B:B) -> 0.24037996 | D5: -0.4 | E5: =CORREL('Sample 1'!I:I,'Sample 1'!I:I) -> 1
B6: Mileage | C6: =CORREL('Sample 1'!C:C,'Sample 1'!B:B) -> -0.77619426 | D6: =CORREL('Sample 1'!C:C,'Sample 1'!F:F) -> 0.74921567 | E6: =CORREL('Sample 1'!C:C,'Sample 1'!I:I) -> 0.10507477 | F6: =CORREL('Sample 1'!C:C,'Sample 1'!C:C) -> 1
B7: Owner count | C7: =CORREL('Sample 1'!L:L,'Sample 1'!B:B) -> -0.69001175 | D7: =CORREL('Sample 1'!L:L,'Sample 1'!F:F) -> 0.83271017 | E7: =CORREL('Sample 1'!L:L,'Sample 1'!I:I) -> -0.016053658 | F7: =CORREL('Sample 1'!L:L,'Sample 1'!C:C) -> 0.63263468 | G7: =CORREL('Sample 1'!L:L,'Sample 1'!L:L) -> 1

Sheet Relation
A1: Corelation | B1: =CORREL('Sample 1'!B2:B101,'Sample 1'!C2:C101) -> -0.77619426
A4: Slope(b) | B4: =SLOPE('Sample 1'!B2:B101,'Sample 1'!C2:C101) -> -0.18431504
D5: For every extra 1 mile → price drops by about £0.18
A6: Intercept(a) | B6: =INTERCEPT('Sample 1'!B2:B101,'Sample 1'!C2:C101) -> 26670.842 | D6: When Mileage = 0, expected price ≈ £26,671

Sheet No. of Owner
A1: No. of Owner | B1: Average of Price
A2: 1-2 | B2: 21290.344
A3: 3-4 | B3: 9610.7
A4: 5-6 | B4: 5514.0909
A5: >7 | B5: 4848.625
